10/24/2016 00:00:14;0002;PBS_Server;Svr;Log;Log opened
10/24/2016 00:00:14;0002;PBS_Server;Svr;PBS_Server;Torque Server Version = 3.0.3, loglevel = 0
10/24/2016 00:05:14;0002;PBS_Server;Svr;PBS_Server;Torque Server Version = 3.0.3, loglevel = 0
10/24/2016 00:09:41;0040;PBS_Server;Svr;aegean;Scheduler was sent the command time
10/24/2016 00:10:14;0002;PBS_Server;Svr;PBS_Server;Torque Server Version = 3.0.3, loglevel = 0
10/24/2016 00:15:14;0002;PBS_Server;Svr;PBS_Server;Torque Server Version = 3.0.3, loglevel = 0
10/24/2016 00:19:41;0040;PBS_Server;Svr;aegean;Scheduler was sent the command time
10/24/2016 00:20:14;0002;PBS_Server;Svr;PBS_Server;Torque Server Version = 3.0.3, loglevel = 0
10/24/2016 00:25:14;0002;PBS_Server;Svr;PBS_Server;Torque Server Version = 3.0.3, loglevel = 0
10/24/2016 00:29:41;0040;PBS_Server;Svr;aegean;Scheduler was sent the command time
10/24/2016 00:30:14;0002;PBS_Server;Svr;PBS_Server;Torque Server Version = 3.0.3, loglevel = 0
10/24/2016 00:35:14;0002;PBS_Server;Svr;PBS_Server;Torque Server Version = 3.0.3, loglevel = 0
10/24/2016 00:39:41;0040;PBS_Server;Svr;aegean;Scheduler was sent the command time
10/24/2016 00:40:14;0002;PBS_Server;Svr;PBS_Server;Torque Server Version = 3.0.3, loglevel = 0
10/24/2016 00:45:14;0002;PBS_Server;Svr;PBS_Server;Torque Server Version = 3.0.3, loglevel = 0
10/24/2016 00:49:41;0040;PBS_Server;Svr;aegean;Scheduler was sent the command time
10/24/2016 00:50:14;0002;PBS_Server;Svr;PBS_Server;Torque Server Version = 3.0.3, loglevel = 0
10/24/2016 00:55:14;0002;PBS_Server;Svr;PBS_Server;Torque Server Version = 3.0.3, loglevel = 0
10/24/2016 00:59:41;0040;PBS_Server;Svr;aegean;Scheduler was sent the command time
10/24/2016 01:00:14;0002;PBS_Server;Svr;PBS_Server;Torque Server Version = 3.0.3, loglevel = 0
10/24/2016 01:05:14;0002;PBS_Server;Svr;PBS_Server;Torque Server Version = 3.0.3, loglevel = 0
10/24/2016 01:09:41;0040;PBS_Server;Svr;aegean;Scheduler was sent the command time
10/24/2016 01:10:14;0002;PBS_Server;Svr;PBS_Server;Torque Server Version = 3.0.3, loglevel = 0
10/24/2016 01:15:14;0002;PBS_Server;Svr;PBS_Server;Torque Server Version = 3.0.3, loglevel = 0
10/24/2016 01:19:41;0040;PBS_Server;Svr;aegean;Scheduler was sent the command time
10/24/2016 01:20:14;0002;PBS_Server;Svr;PBS_Server;Torque Server Version = 3.0.3, loglevel = 0
10/24/2016 01:25:14;0002;PBS_Server;Svr;PBS_Server;Torque Server Version = 3.0.3, loglevel = 0
10/24/2016 01:29:41;0040;PBS_Server;Svr;aegean;Scheduler was sent the command time
10/24/2016 01:30:14;0002;PBS_Server;Svr;PBS_Server;Torque Server Version = 3.0.3, loglevel = 0
10/24/2016 01:35:14;0002;PBS_Server;Svr;PBS_Server;Torque Server Version = 3.0.3, loglevel = 0
10/24/2016 01:39:41;0040;PBS_Server;Svr;aegean;Scheduler was sent the command time
10/24/2016 01:40:14;0002;PBS_Server;Svr;PBS_Server;Torque Server Version = 3.0.3, loglevel = 0
10/24/2016 01:45:14;0002;PBS_Server;Svr;PBS_Server;Torque Server Version = 3.0.3, loglevel = 0
10/24/2016 01:49:41;0040;PBS_Server;Svr;aegean;Scheduler was sent the command time
10/24/2016 01:50:14;0002;PBS_Server;Svr;PBS_Server;Torque Server Version = 3.0.3, loglevel = 0
10/24/2016 01:55:14;0002;PBS_Server;Svr;PBS_Server;Torque Server Version = 3.0.3, loglevel = 0
10/24/2016 01:59:41;0040;PBS_Server;Svr;aegean;Scheduler was sent the command time
10/24/2016 02:00:14;0002;PBS_Server;Svr;PBS_Server;Torque Server Version = 3.0.3, loglevel = 0
10/24/2016 02:05:14;0002;PBS_Server;Svr;PBS_Server;Torque Server Version = 3.0.3, loglevel = 0
10/24/2016 02:09:41;0040;PBS_Server;Svr;aegean;Scheduler was sent the command time
10/24/2016 02:10:14;0002;PBS_Server;Svr;PBS_Server;Torque Server Version = 3.0.3, loglevel = 0
10/24/2016 02:15:14;0002;PBS_Server;Svr;PBS_Server;Torque Server Version = 3.0.3, loglevel = 0
10/24/2016 02:19:41;0040;PBS_Server;Svr;aegean;Scheduler was sent the command time
10/24/2016 02:20:14;0002;PBS_Server;Svr;PBS_Server;Torque Server Version = 3.0.3, loglevel = 0
10/24/2016 02:25:14;0002;PBS_Server;Svr;PBS_Server;Torque Server Version = 3.0.3, loglevel = 0
10/24/2016 02:29:41;0040;PBS_Server;Svr;aegean;Scheduler was sent the command time
10/24/2016 02:30:14;0002;PBS_Server;Svr;PBS_Server;Torque Server Version = 3.0.3, loglevel = 0
10/24/2016 02:35:14;0002;PBS_Server;Svr;PBS_Server;Torque Server Version = 3.0.3, loglevel = 0
10/24/2016 02:39:41;0040;PBS_Server;Svr;aegean;Scheduler was sent the command time
10/24/2016 02:40:14;0002;PBS_Server;Svr;PBS_Server;Torque Server Version = 3.0.3, loglevel = 0
10/24/2016 02:45:14;0002;PBS_Server;Svr;PBS_Server;Torque Server Version = 3.0.3, loglevel = 0
10/24/2016 02:49:41;0040;PBS_Server;Svr;aegean;Scheduler was sent the command time
10/24/2016 02:50:14;0002;PBS_Server;Svr;PBS_Server;Torque Server Version = 3.0.3, loglevel = 0
10/24/2016 02:55:14;0002;PBS_Server;Svr;PBS_Server;Torque Server Version = 3.0.3, loglevel = 0
10/24/2016 02:59:41;0040;PBS_Server;Svr;aegean;Scheduler was sent the command time
10/24/2016 03:00:14;0002;PBS_Server;Svr;PBS_Server;Torque Server Version = 3.0.3, loglevel = 0
10/24/2016 03:05:14;0002;PBS_Server;Svr;PBS_Server;Torque Server Version = 3.0.3, loglevel = 0
10/24/2016 03:09:41;0040;PBS_Server;Svr;aegean;Scheduler was sent the command time
10/24/2016 03:10:14;0002;PBS_Server;Svr;PBS_Server;Torque Server Version = 3.0.3, loglevel = 0
10/24/2016 03:15:14;0002;PBS_Server;Svr;PBS_Server;Torque Server Version = 3.0.3, loglevel = 0
10/24/2016 03:19:41;0040;PBS_Server;Svr;aegean;Scheduler was sent the command time
10/24/2016 03:20:14;0002;PBS_Server;Svr;PBS_Server;Torque Server Version = 3.0.3, loglevel = 0
10/24/2016 03:25:14;0002;PBS_Server;Svr;PBS_Server;Torque Server Version = 3.0.3, loglevel = 0
10/24/2016 03:29:41;0040;PBS_Server;Svr;aegean;Scheduler was sent the command time
10/24/2016 03:30:14;0002;PBS_Server;Svr;PBS_Server;Torque Server Version = 3.0.3, loglevel = 0
10/24/2016 03:35:14;0002;PBS_Server;Svr;PBS_Server;Torque Server Version = 3.0.3, loglevel = 0
10/24/2016 03:39:41;0040;PBS_Server;Svr;aegean;Scheduler was sent the command time
10/24/2016 03:40:14;0002;PBS_Server;Svr;PBS_Server;Torque Server Version = 3.0.3, loglevel = 0
10/24/2016 03:45:14;0002;PBS_Server;Svr;PBS_Server;Torque Server Version = 3.0.3, loglevel = 0
10/24/2016 03:49:41;0040;PBS_Server;Svr;aegean;Scheduler was sent the command time
10/24/2016 03:50:14;0002;PBS_Server;Svr;PBS_Server;Torque Server Version = 3.0.3, loglevel = 0
10/24/2016 03:55:14;0002;PBS_Server;Svr;PBS_Server;Torque Server Version = 3.0.3, loglevel = 0
10/24/2016 03:59:41;0040;PBS_Server;Svr;aegean;Scheduler was sent the command time
10/24/2016 04:00:14;0002;PBS_Server;Svr;PBS_Server;Torque Server Version = 3.0.3, loglevel = 0
10/24/2016 04:05:14;0002;PBS_Server;Svr;PBS_Server;Torque Server Version = 3.0.3, loglevel = 0
10/24/2016 04:09:41;0040;PBS_Server;Svr;aegean;Scheduler was sent the command time
10/24/2016 04:10:14;0002;PBS_Server;Svr;PBS_Server;Torque Server Version = 3.0.3, loglevel = 0
10/24/2016 04:15:14;0002;PBS_Server;Svr;PBS_Server;Torque Server Version = 3.0.3, loglevel = 0
10/24/2016 04:19:41;0040;PBS_Server;Svr;aegean;Scheduler was sent the command time
10/24/2016 04:20:14;0002;PBS_Server;Svr;PBS_Server;Torque Server Version = 3.0.3, loglevel = 0
10/24/2016 04:25:14;0002;PBS_Server;Svr;PBS_Server;Torque Server Version = 3.0.3, loglevel = 0
10/24/2016 04:29:41;0040;PBS_Server;Svr;aegean;Scheduler was sent the command time
10/24/2016 04:30:14;0002;PBS_Server;Svr;PBS_Server;Torque Server Version = 3.0.3, loglevel = 0
10/24/2016 04:35:14;0002;PBS_Server;Svr;PBS_Server;Torque Server Version = 3.0.3, loglevel = 0
10/24/2016 04:39:41;0040;PBS_Server;Svr;aegean;Scheduler was sent the command time
10/24/2016 04:40:14;0002;PBS_Server;Svr;PBS_Server;Torque Server Version = 3.0.3, loglevel = 0
10/24/2016 04:45:14;0002;PBS_Server;Svr;PBS_Server;Torque Server Version = 3.0.3, loglevel = 0
10/24/2016 04:49:41;0040;PBS_Server;Svr;aegean;Scheduler was sent the command time
10/24/2016 04:50:14;0002;PBS_Server;Svr;PBS_Server;Torque Server Version = 3.0.3, loglevel = 0
10/24/2016 04:55:14;0002;PBS_Server;Svr;PBS_Server;Torque Server Version = 3.0.3, loglevel = 0
10/24/2016 04:59:41;0040;PBS_Server;Svr;aegean;Scheduler was sent the command time
10/24/2016 05:00:14;0002;PBS_Server;Svr;PBS_Server;Torque Server Version = 3.0.3, loglevel = 0
10/24/2016 05:05:14;0002;PBS_Server;Svr;PBS_Server;Torque Server Version = 3.0.3, loglevel = 0
10/24/2016 05:09:41;0040;PBS_Server;Svr;aegean;Scheduler was sent the command time
10/24/2016 05:10:14;0002;PBS_Server;Svr;PBS_Server;Torque Server Version = 3.0.3, loglevel = 0
10/24/2016 05:15:14;0002;PBS_Server;Svr;PBS_Server;Torque Server Version = 3.0.3, loglevel = 0
10/24/2016 05:19:41;0040;PBS_Server;Svr;aegean;Scheduler was sent the command time
10/24/2016 05:20:14;0002;PBS_Server;Svr;PBS_Server;Torque Server Version = 3.0.3, loglevel = 0
10/24/2016 05:25:14;0002;PBS_Server;Svr;PBS_Server;Torque Server Version = 3.0.3, loglevel = 0
10/24/2016 05:29:41;0040;PBS_Server;Svr;aegean;Scheduler was sent the command time
10/24/2016 05:30:14;0002;PBS_Server;Svr;PBS_Server;Torque Server Version = 3.0.3, loglevel = 0
10/24/2016 05:35:14;0002;PBS_Server;Svr;PBS_Server;Torque Server Version = 3.0.3, loglevel = 0
10/24/2016 05:39:41;0040;PBS_Server;Svr;aegean;Scheduler was sent the command time
10/24/2016 05:40:14;0002;PBS_Server;Svr;PBS_Server;Torque Server Version = 3.0.3, loglevel = 0
10/24/2016 05:45:14;0002;PBS_Server;Svr;PBS_Server;Torque Server Version = 3.0.3, loglevel = 0
10/24/2016 05:49:41;0040;PBS_Server;Svr;aegean;Scheduler was sent the command time
10/24/2016 05:50:14;0002;PBS_Server;Svr;PBS_Server;Torque Server Version = 3.0.3, loglevel = 0
10/24/2016 05:55:14;0002;PBS_Server;Svr;PBS_Server;Torque Server Version = 3.0.3, loglevel = 0
10/24/2016 05:59:41;0040;PBS_Server;Svr;aegean;Scheduler was sent the command time
10/24/2016 06:00:14;0002;PBS_Server;Svr;PBS_Server;Torque Server Version = 3.0.3, loglevel = 0
10/24/2016 06:05:14;0002;PBS_Server;Svr;PBS_Server;Torque Server Version = 3.0.3, loglevel = 0
10/24/2016 06:09:41;0040;PBS_Server;Svr;aegean;Scheduler was sent the command time
10/24/2016 06:10:14;0002;PBS_Server;Svr;PBS_Server;Torque Server Version = 3.0.3, loglevel = 0
10/24/2016 06:15:14;0002;PBS_Server;Svr;PBS_Server;Torque Server Version = 3.0.3, loglevel = 0
10/24/2016 06:19:41;0040;PBS_Server;Svr;aegean;Scheduler was sent the command time
10/24/2016 06:20:14;0002;PBS_Server;Svr;PBS_Server;Torque Server Version = 3.0.3, loglevel = 0
10/24/2016 06:25:14;0002;PBS_Server;Svr;PBS_Server;Torque Server Version = 3.0.3, loglevel = 0
10/24/2016 06:29:41;0040;PBS_Server;Svr;aegean;Scheduler was sent the command time
10/24/2016 06:30:14;0002;PBS_Server;Svr;PBS_Server;Torque Server Version = 3.0.3, loglevel = 0
10/24/2016 06:35:14;0002;PBS_Server;Svr;PBS_Server;Torque Server Version = 3.0.3, loglevel = 0
10/24/2016 06:39:41;0040;PBS_Server;Svr;aegean;Scheduler was sent the command time
10/24/2016 06:40:14;0002;PBS_Server;Svr;PBS_Server;Torque Server Version = 3.0.3, loglevel = 0
10/24/2016 06:45:14;0002;PBS_Server;Svr;PBS_Server;Torque Server Version = 3.0.3, loglevel = 0
10/24/2016 06:49:41;0040;PBS_Server;Svr;aegean;Scheduler was sent the command time
10/24/2016 06:50:14;0002;PBS_Server;Svr;PBS_Server;Torque Server Version = 3.0.3, loglevel = 0
10/24/2016 06:55:14;0002;PBS_Server;Svr;PBS_Server;Torque Server Version = 3.0.3, loglevel = 0
10/24/2016 06:59:41;0040;PBS_Server;Svr;aegean;Scheduler was sent the command time
10/24/2016 07:00:14;0002;PBS_Server;Svr;PBS_Server;Torque Server Version = 3.0.3, loglevel = 0
10/24/2016 07:05:14;0002;PBS_Server;Svr;PBS_Server;Torque Server Version = 3.0.3, loglevel = 0
10/24/2016 07:09:41;0040;PBS_Server;Svr;aegean;Scheduler was sent the command time
10/24/2016 07:10:14;0002;PBS_Server;Svr;PBS_Server;Torque Server Version = 3.0.3, loglevel = 0
10/24/2016 07:15:14;0002;PBS_Server;Svr;PBS_Server;Torque Server Version = 3.0.3, loglevel = 0
10/24/2016 07:19:41;0040;PBS_Server;Svr;aegean;Scheduler was sent the command time
10/24/2016 07:20:14;0002;PBS_Server;Svr;PBS_Server;Torque Server Version = 3.0.3, loglevel = 0
10/24/2016 07:25:14;0002;PBS_Server;Svr;PBS_Server;Torque Server Version = 3.0.3, loglevel = 0
10/24/2016 07:29:41;0040;PBS_Server;Svr;aegean;Scheduler was sent the command time
10/24/2016 07:30:14;0002;PBS_Server;Svr;PBS_Server;Torque Server Version = 3.0.3, loglevel = 0
10/24/2016 07:35:14;0002;PBS_Server;Svr;PBS_Server;Torque Server Version = 3.0.3, loglevel = 0
10/24/2016 07:39:41;0040;PBS_Server;Svr;aegean;Scheduler was sent the command time
10/24/2016 07:40:14;0002;PBS_Server;Svr;PBS_Server;Torque Server Version = 3.0.3, loglevel = 0
10/24/2016 07:45:14;0002;PBS_Server;Svr;PBS_Server;Torque Server Version = 3.0.3, loglevel = 0
10/24/2016 07:49:41;0040;PBS_Server;Svr;aegean;Scheduler was sent the command time
10/24/2016 07:50:14;0002;PBS_Server;Svr;PBS_Server;Torque Server Version = 3.0.3, loglevel = 0
10/24/2016 07:55:14;0002;PBS_Server;Svr;PBS_Server;Torque Server Version = 3.0.3, loglevel = 0
10/24/2016 07:59:41;0040;PBS_Server;Svr;aegean;Scheduler was sent the command time
10/24/2016 08:00:14;0002;PBS_Server;Svr;PBS_Server;Torque Server Version = 3.0.3, loglevel = 0
10/24/2016 08:05:14;0002;PBS_Server;Svr;PBS_Server;Torque Server Version = 3.0.3, loglevel = 0
10/24/2016 08:09:41;0040;PBS_Server;Svr;aegean;Scheduler was sent the command time
10/24/2016 08:10:14;0002;PBS_Server;Svr;PBS_Server;Torque Server Version = 3.0.3, loglevel = 0
10/24/2016 08:15:14;0002;PBS_Server;Svr;PBS_Server;Torque Server Version = 3.0.3, loglevel = 0
10/24/2016 08:19:41;0040;PBS_Server;Svr;aegean;Scheduler was sent the command time
10/24/2016 08:20:14;0002;PBS_Server;Svr;PBS_Server;Torque Server Version = 3.0.3, loglevel = 0
10/24/2016 08:25:14;0002;PBS_Server;Svr;PBS_Server;Torque Server Version = 3.0.3, loglevel = 0
10/24/2016 08:29:41;0040;PBS_Server;Svr;aegean;Scheduler was sent the command time
10/24/2016 08:30:14;0002;PBS_Server;Svr;PBS_Server;Torque Server Version = 3.0.3, loglevel = 0
10/24/2016 08:35:14;0002;PBS_Server;Svr;PBS_Server;Torque Server Version = 3.0.3, loglevel = 0
10/24/2016 08:39:41;0040;PBS_Server;Svr;aegean;Scheduler was sent the command time
10/24/2016 08:40:14;0002;PBS_Server;Svr;PBS_Server;Torque Server Version = 3.0.3, loglevel = 0
10/24/2016 08:45:14;0002;PBS_Server;Svr;PBS_Server;Torque Server Version = 3.0.3, loglevel = 0
10/24/2016 08:49:41;0040;PBS_Server;Svr;aegean;Scheduler was sent the command time
10/24/2016 08:50:14;0002;PBS_Server;Svr;PBS_Server;Torque Server Version = 3.0.3, loglevel = 0
10/24/2016 08:55:14;0002;PBS_Server;Svr;PBS_Server;Torque Server Version = 3.0.3, loglevel = 0
10/24/2016 08:59:41;0040;PBS_Server;Svr;aegean;Scheduler was sent the command time
10/24/2016 09:00:14;0002;PBS_Server;Svr;PBS_Server;Torque Server Version = 3.0.3, loglevel = 0
10/24/2016 09:05:14;0002;PBS_Server;Svr;PBS_Server;Torque Server Version = 3.0.3, loglevel = 0
10/24/2016 09:09:41;0040;PBS_Server;Svr;aegean;Scheduler was sent the command time
10/24/2016 09:10:14;0002;PBS_Server;Svr;PBS_Server;Torque Server Version = 3.0.3, loglevel = 0
10/24/2016 09:15:14;0002;PBS_Server;Svr;PBS_Server;Torque Server Version = 3.0.3, loglevel = 0
10/24/2016 09:19:41;0040;PBS_Server;Svr;aegean;Scheduler was sent the command time
10/24/2016 09:20:14;0002;PBS_Server;Svr;PBS_Server;Torque Server Version = 3.0.3, loglevel = 0
10/24/2016 09:25:14;0002;PBS_Server;Svr;PBS_Server;Torque Server Version = 3.0.3, loglevel = 0
10/24/2016 09:29:41;0040;PBS_Server;Svr;aegean;Scheduler was sent the command time
10/24/2016 09:30:14;0002;PBS_Server;Svr;PBS_Server;Torque Server Version = 3.0.3, loglevel = 0
10/24/2016 09:35:14;0002;PBS_Server;Svr;PBS_Server;Torque Server Version = 3.0.3, loglevel = 0
10/24/2016 09:38:52;0100;PBS_Server;Job;91711.aegean;enqueuing into batch, state 1 hop 1
10/24/2016 09:38:52;0002;PBS_Server;Svr;Act;Account file /var/spool/torque/server_priv/accounting/20161024 opened
10/24/2016 09:38:52;0008;PBS_Server;Job;91711.aegean;Job Queued at request of kkan@aegean, owner = kkan@aegean, job name = aga.sh, queue = batch
10/24/2016 09:38:52;0040;PBS_Server;Svr;aegean;Scheduler was sent the command new
10/24/2016 09:38:53;0008;PBS_Server;Job;91711.aegean;Job Run at request of root@aegean
10/24/2016 09:38:53;000d;PBS_Server;Job;91711.aegean;Not sending email: User does not want mail of this type.
10/24/2016 09:40:14;0002;PBS_Server;Svr;PBS_Server;Torque Server Version = 3.0.3, loglevel = 0
10/24/2016 09:40:22;000d;PBS_Server;Job;91711.aegean;Not sending email: User does not want mail of this type.
10/24/2016 09:40:22;0010;PBS_Server;Job;91711.aegean;Exit_status=0 resources_used.cput=00:02:54 resources_used.mem=1213920kb resources_used.vmem=2932580kb resources_used.walltime=00:01:29
10/24/2016 09:40:22;0008;PBS_Server;Job;NULL;on_job_exit valid pjob: 0x3191250 (substate=50)
10/24/2016 09:40:22;0008;PBS_Server;Job;NULL;on_job_exit valid pjob: 0x3191250 (substate=51)
10/24/2016 09:40:22;0008;PBS_Server;Job;NULL;on_job_exit valid pjob: 0x3191250 (substate=52)
10/24/2016 09:40:22;0008;PBS_Server;Job;NULL;on_job_exit valid pjob: 0x3191250 (substate=53)
10/24/2016 09:40:22;0040;PBS_Server;Svr;aegean;Scheduler was sent the command term
10/24/2016 09:45:14;0002;PBS_Server;Svr;PBS_Server;Torque Server Version = 3.0.3, loglevel = 0
10/24/2016 09:45:22;0008;PBS_Server;Job;NULL;on_job_exit valid pjob: 0x3191250 (substate=59)
10/24/2016 09:45:22;0100;PBS_Server;Job;91711.aegean;dequeuing from batch, state COMPLETE
10/24/2016 09:45:22;0040;PBS_Server;Svr;aegean;Scheduler was sent the command term
10/24/2016 09:50:14;0002;PBS_Server;Svr;PBS_Server;Torque Server Version = 3.0.3, loglevel = 0
10/24/2016 09:55:14;0002;PBS_Server;Svr;PBS_Server;Torque Server Version = 3.0.3, loglevel = 0
10/24/2016 09:55:22;0040;PBS_Server;Svr;aegean;Scheduler was sent the command time
10/24/2016 09:57:22;0100;PBS_Server;Job;91712.aegean;enqueuing into batch, state 1 hop 1
10/24/2016 09:57:22;0008;PBS_Server;Job;91712.aegean;Job Queued at request of kkan@aegean, owner = kkan@aegean, job name = aga.sh, queue = batch
10/24/2016 09:57:22;0040;PBS_Server;Svr;aegean;Scheduler was sent the command new
10/24/2016 09:57:23;0008;PBS_Server;Job;91712.aegean;Job Run at request of root@aegean
10/24/2016 09:57:23;000d;PBS_Server;Job;91712.aegean;Not sending email: User does not want mail of this type.
10/24/2016 09:58:53;000d;PBS_Server;Job;91712.aegean;Not sending email: User does not want mail of this type.
10/24/2016 09:58:53;0010;PBS_Server;Job;91712.aegean;Exit_status=0 resources_used.cput=00:02:56 resources_used.mem=1213964kb resources_used.vmem=2932580kb resources_used.walltime=00:01:30
10/24/2016 09:58:53;0008;PBS_Server;Job;NULL;on_job_exit valid pjob: 0x3191250 (substate=50)
10/24/2016 09:58:53;0008;PBS_Server;Job;NULL;on_job_exit valid pjob: 0x3191250 (substate=51)
10/24/2016 09:58:53;0008;PBS_Server;Job;NULL;on_job_exit valid pjob: 0x3191250 (substate=52)
10/24/2016 09:58:53;0008;PBS_Server;Job;NULL;on_job_exit valid pjob: 0x3191250 (substate=53)
10/24/2016 09:58:53;0040;PBS_Server;Svr;aegean;Scheduler was sent the command term
10/24/2016 10:00:14;0002;PBS_Server;Svr;PBS_Server;Torque Server Version = 3.0.3, loglevel = 0
10/24/2016 10:02:31;0100;PBS_Server;Job;91713.aegean;enqueuing into batch, state 1 hop 1
10/24/2016 10:02:31;0008;PBS_Server;Job;91713.aegean;Job Queued at request of kkan@aegean, owner = kkan@aegean, job name = aga.sh, queue = batch
10/24/2016 10:02:31;0040;PBS_Server;Svr;aegean;Scheduler was sent the command new
10/24/2016 10:02:32;0008;PBS_Server;Job;91713.aegean;Job Run at request of root@aegean
10/24/2016 10:02:32;000d;PBS_Server;Job;91713.aegean;Not sending email: User does not want mail of this type.
10/24/2016 10:03:53;0008;PBS_Server;Job;NULL;on_job_exit valid pjob: 0x3191250 (substate=59)
10/24/2016 10:03:53;0100;PBS_Server;Job;91712.aegean;dequeuing from batch, state COMPLETE
10/24/2016 10:03:53;0040;PBS_Server;Svr;aegean;Scheduler was sent the command term
10/24/2016 10:04:02;000d;PBS_Server;Job;91713.aegean;Not sending email: User does not want mail of this type.
10/24/2016 10:04:02;0010;PBS_Server;Job;91713.aegean;Exit_status=0 resources_used.cput=00:02:56 resources_used.mem=1213864kb resources_used.vmem=2932444kb resources_used.walltime=00:01:30
10/24/2016 10:04:02;0008;PBS_Server;Job;NULL;on_job_exit valid pjob: 0x324ba50 (substate=50)
10/24/2016 10:04:02;0008;PBS_Server;Job;NULL;on_job_exit valid pjob: 0x324ba50 (substate=51)
10/24/2016 10:04:02;0008;PBS_Server;Job;NULL;on_job_exit valid pjob: 0x324ba50 (substate=52)
10/24/2016 10:04:02;0008;PBS_Server;Job;NULL;on_job_exit valid pjob: 0x324ba50 (substate=53)
10/24/2016 10:04:02;0040;PBS_Server;Svr;aegean;Scheduler was sent the command term
10/24/2016 10:05:14;0002;PBS_Server;Svr;PBS_Server;Torque Server Version = 3.0.3, loglevel = 0
10/24/2016 10:06:05;0100;PBS_Server;Job;91714.aegean;enqueuing into batch, state 1 hop 1
10/24/2016 10:06:05;0008;PBS_Server;Job;91714.aegean;Job Queued at request of kkan@aegean, owner = kkan@aegean, job name = aga.sh, queue = batch
10/24/2016 10:06:05;0040;PBS_Server;Svr;aegean;Scheduler was sent the command new
10/24/2016 10:06:06;0008;PBS_Server;Job;91714.aegean;Job Run at request of root@aegean
10/24/2016 10:06:06;000d;PBS_Server;Job;91714.aegean;Not sending email: User does not want mail of this type.
10/24/2016 10:07:37;000d;PBS_Server;Job;91714.aegean;Not sending email: User does not want mail of this type.
10/24/2016 10:07:37;0010;PBS_Server;Job;91714.aegean;Exit_status=0 resources_used.cput=00:02:56 resources_used.mem=1204124kb resources_used.vmem=2932580kb resources_used.walltime=00:01:31
10/24/2016 10:07:37;0008;PBS_Server;Job;NULL;on_job_exit valid pjob: 0x3191250 (substate=50)
10/24/2016 10:07:37;0008;PBS_Server;Job;NULL;on_job_exit valid pjob: 0x3191250 (substate=51)
10/24/2016 10:07:37;0008;PBS_Server;Job;NULL;on_job_exit valid pjob: 0x3191250 (substate=52)
10/24/2016 10:07:37;0008;PBS_Server;Job;NULL;on_job_exit valid pjob: 0x3191250 (substate=53)
10/24/2016 10:07:37;0040;PBS_Server;Svr;aegean;Scheduler was sent the command term
10/24/2016 10:09:02;0008;PBS_Server;Job;NULL;on_job_exit valid pjob: 0x324ba50 (substate=59)
10/24/2016 10:09:02;0100;PBS_Server;Job;91713.aegean;dequeuing from batch, state COMPLETE
10/24/2016 10:09:02;0040;PBS_Server;Svr;aegean;Scheduler was sent the command term
10/24/2016 10:10:14;0002;PBS_Server;Svr;PBS_Server;Torque Server Version = 3.0.3, loglevel = 0
10/24/2016 10:12:37;0008;PBS_Server;Job;NULL;on_job_exit valid pjob: 0x3191250 (substate=59)
10/24/2016 10:12:37;0100;PBS_Server;Job;91714.aegean;dequeuing from batch, state COMPLETE
10/24/2016 10:12:37;0040;PBS_Server;Svr;aegean;Scheduler was sent the command term
10/24/2016 10:12:59;0008;PBS_Server;Job;91487.aegean;Job deleted at request of dangelid@aegean
10/24/2016 10:12:59;0008;PBS_Server;Job;91487.aegean;Job sent signal SIGTERM on delete
10/24/2016 10:12:59;0100;PBS_Server;Job;91715.aegean;enqueuing into batch, state 1 hop 1
10/24/2016 10:12:59;0008;PBS_Server;Job;91715.aegean;Job Queued at request of dangelid@aegean, owner = dangelid@aegean, job name = Sloshing_100x20x100_1LVReBB, queue = batch
10/24/2016 10:12:59;0040;PBS_Server;Svr;aegean;Scheduler was sent the command new
10/24/2016 10:13:00;0010;PBS_Server;Job;91487.aegean;Exit_status=271 resources_used.cput=7664:39:35 resources_used.mem=14654092kb resources_used.vmem=25849360kb resources_used.walltime=119:51:50
10/24/2016 10:13:00;0008;PBS_Server;Job;NULL;on_job_exit valid pjob: 0x31d5730 (substate=50)
10/24/2016 10:13:00;0008;PBS_Server;Job;NULL;on_job_exit valid pjob: 0x31d5730 (substate=51)
10/24/2016 10:13:00;0008;PBS_Server;Job;NULL;on_job_exit valid pjob: 0x31d5730 (substate=52)
10/24/2016 10:13:00;0008;PBS_Server;Job;NULL;on_job_exit valid pjob: 0x31d5730 (substate=53)
10/24/2016 10:13:00;0040;PBS_Server;Svr;aegean;Scheduler was sent the command term
10/24/2016 10:13:16;0100;PBS_Server;Job;91716.aegean;enqueuing into long, state 1 hop 1
10/24/2016 10:13:16;0008;PBS_Server;Job;91716.aegean;Job Queued at request of dangelid@aegean, owner = dangelid@aegean, job name = Sloshing_100x20x100_1LVReBB, queue = long
10/24/2016 10:13:16;0040;PBS_Server;Svr;aegean;Scheduler was sent the command new
10/24/2016 10:13:17;0008;PBS_Server;Job;91716.aegean;Job Run at request of root@aegean
10/24/2016 10:13:17;000d;PBS_Server;Job;91716.aegean;Not sending email: User does not want mail of this type.
10/24/2016 10:13:27;0008;PBS_Server;Job;91715.aegean;Job deleted at request of dangelid@aegean
10/24/2016 10:15:09;0008;PBS_Server;Job;91704.aegean;Job deleted at request of chaw0023@aegean
10/24/2016 10:15:09;0008;PBS_Server;Job;91704.aegean;Job sent signal SIGTERM on delete
10/24/2016 10:15:11;0008;PBS_Server;Job;91704.aegean;Job sent signal SIGKILL on delete
10/24/2016 10:15:12;0010;PBS_Server;Job;91704.aegean;Exit_status=271 resources_used.cput=4952:17:27 resources_used.mem=433956220kb resources_used.vmem=498336000kb resources_used.walltime=17:14:21
10/24/2016 10:15:12;0008;PBS_Server;Job;NULL;on_job_exit valid pjob: 0x31e7d80 (substate=50)
10/24/2016 10:15:12;0008;PBS_Server;Job;NULL;on_job_exit valid pjob: 0x31e7d80 (substate=51)
10/24/2016 10:15:12;0008;PBS_Server;Job;NULL;on_job_exit valid pjob: 0x31e7d80 (substate=52)
10/24/2016 10:15:12;0008;PBS_Server;Job;NULL;on_job_exit valid pjob: 0x31e7d80 (substate=53)
10/24/2016 10:15:12;0040;PBS_Server;Svr;aegean;Scheduler was sent the command term
10/24/2016 10:15:13;0008;PBS_Server;Job;91705.aegean;Job Run at request of root@aegean
10/24/2016 10:15:13;0008;PBS_Server;Job;91708.aegean;Job Run at request of root@aegean
10/24/2016 10:15:14;0002;PBS_Server;Svr;PBS_Server;Torque Server Version = 3.0.3, loglevel = 0
10/24/2016 10:15:20;000d;PBS_Server;Job;91708.aegean;Not sending email: User does not want mail of this type.
10/24/2016 10:15:20;0010;PBS_Server;Job;91708.aegean;Exit_status=2 resources_used.cput=00:01:40 resources_used.mem=596kb resources_used.vmem=13464kb resources_used.walltime=00:00:03
10/24/2016 10:15:20;0008;PBS_Server;Job;NULL;on_job_exit valid pjob: 0x31830a0 (substate=50)
10/24/2016 10:15:20;0008;PBS_Server;Job;NULL;on_job_exit valid pjob: 0x31830a0 (substate=51)
10/24/2016 10:15:20;0008;PBS_Server;Job;NULL;on_job_exit valid pjob: 0x31830a0 (substate=52)
10/24/2016 10:15:20;0008;PBS_Server;Job;NULL;on_job_exit valid pjob: 0x31830a0 (substate=53)
10/24/2016 10:15:20;0040;PBS_Server;Svr;aegean;Scheduler was sent the command term
10/24/2016 10:15:21;0008;PBS_Server;Job;91710.aegean;Job Run at request of root@aegean
10/24/2016 10:15:21;000d;PBS_Server;Job;91710.aegean;Not sending email: User does not want mail of this type.
10/24/2016 10:15:24;000d;PBS_Server;Job;91710.aegean;Not sending email: User does not want mail of this type.
10/24/2016 10:15:24;0010;PBS_Server;Job;91710.aegean;Exit_status=2 resources_used.cput=00:01:37 resources_used.mem=596kb resources_used.vmem=13464kb resources_used.walltime=00:00:03
10/24/2016 10:15:24;0008;PBS_Server;Job;NULL;on_job_exit valid pjob: 0x318ff90 (substate=50)
10/24/2016 10:15:24;0008;PBS_Server;Job;NULL;on_job_exit valid pjob: 0x318ff90 (substate=51)
10/24/2016 10:15:24;0008;PBS_Server;Job;NULL;on_job_exit valid pjob: 0x318ff90 (substate=52)
10/24/2016 10:15:24;0008;PBS_Server;Job;NULL;on_job_exit valid pjob: 0x318ff90 (substate=53)
10/24/2016 10:15:24;0040;PBS_Server;Svr;aegean;Scheduler was sent the command term
10/24/2016 10:15:59;000d;PBS_Server;Job;91705.aegean;Not sending email: User does not want mail of this type.
10/24/2016 10:18:00;0008;PBS_Server;Job;NULL;on_job_exit valid pjob: 0x31d5730 (substate=59)
10/24/2016 10:18:00;0100;PBS_Server;Job;91487.aegean;dequeuing from batch, state COMPLETE
10/24/2016 10:18:00;0040;PBS_Server;Svr;aegean;Scheduler was sent the command term
10/24/2016 10:18:27;0008;PBS_Server;Job;NULL;on_job_exit valid pjob: 0x3191250 (substate=59)
10/24/2016 10:18:27;0100;PBS_Server;Job;91715.aegean;dequeuing from batch, state COMPLETE
10/24/2016 10:18:27;0040;PBS_Server;Svr;aegean;Scheduler was sent the command term
10/24/2016 10:20:12;0008;PBS_Server;Job;NULL;on_job_exit valid pjob: 0x31e7d80 (substate=59)
10/24/2016 10:20:12;0100;PBS_Server;Job;91704.aegean;dequeuing from batch, state COMPLETE
10/24/2016 10:20:12;0040;PBS_Server;Svr;aegean;Scheduler was sent the command term
10/24/2016 10:20:14;0002;PBS_Server;Svr;PBS_Server;Torque Server Version = 3.0.3, loglevel = 0
10/24/2016 10:20:20;0008;PBS_Server;Job;NULL;on_job_exit valid pjob: 0x31830a0 (substate=59)
10/24/2016 10:20:20;0100;PBS_Server;Job;91708.aegean;dequeuing from batch, state COMPLETE
10/24/2016 10:20:20;0040;PBS_Server;Svr;aegean;Scheduler was sent the command term
10/24/2016 10:20:24;0008;PBS_Server;Job;NULL;on_job_exit valid pjob: 0x318ff90 (substate=59)
10/24/2016 10:20:24;0100;PBS_Server;Job;91710.aegean;dequeuing from batch, state COMPLETE
10/24/2016 10:20:24;0040;PBS_Server;Svr;aegean;Scheduler was sent the command term
10/24/2016 10:25:14;0002;PBS_Server;Svr;PBS_Server;Torque Server Version = 3.0.3, loglevel = 0
10/24/2016 10:30:14;0002;PBS_Server;Svr;PBS_Server;Torque Server Version = 3.0.3, loglevel = 0
10/24/2016 10:30:24;0040;PBS_Server;Svr;aegean;Scheduler was sent the command time
10/24/2016 10:31:10;0008;PBS_Server;Job;91651.aegean;Job deleted at request of dangelid@aegean
10/24/2016 10:31:10;0008;PBS_Server;Job;91651.aegean;Job sent signal SIGTERM on delete
10/24/2016 10:31:12;0008;PBS_Server;Job;91651.aegean;Job sent signal SIGKILL on delete
10/24/2016 10:31:12;0010;PBS_Server;Job;91651.aegean;Exit_status=271 resources_used.cput=6645:55:59 resources_used.mem=54736560kb resources_used.vmem=69216212kb resources_used.walltime=69:22:59
10/24/2016 10:31:12;0008;PBS_Server;Job;NULL;on_job_exit valid pjob: 0x32438d0 (substate=50)
10/24/2016 10:31:12;0008;PBS_Server;Job;NULL;on_job_exit valid pjob: 0x32438d0 (substate=51)
10/24/2016 10:31:12;0008;PBS_Server;Job;NULL;on_job_exit valid pjob: 0x32438d0 (substate=52)
10/24/2016 10:31:12;0008;PBS_Server;Job;NULL;on_job_exit valid pjob: 0x32438d0 (substate=53)
10/24/2016 10:31:12;0040;PBS_Server;Svr;aegean;Scheduler was sent the command term
10/24/2016 10:31:22;0008;PBS_Server;Job;91696.aegean;Job deleted at request of dangelid@aegean
10/24/2016 10:31:22;0008;PBS_Server;Job;91696.aegean;Job sent signal SIGTERM on delete
10/24/2016 10:31:24;0008;PBS_Server;Job;91696.aegean;Job sent signal SIGKILL on delete
10/24/2016 10:31:24;0010;PBS_Server;Job;91696.aegean;Exit_status=271 resources_used.cput=2123:45:19 resources_used.mem=28494248kb resources_used.vmem=43406592kb resources_used.walltime=22:19:08
10/24/2016 10:31:24;0008;PBS_Server;Job;NULL;on_job_exit valid pjob: 0x30fe8d0 (substate=50)
10/24/2016 10:31:24;0008;PBS_Server;Job;NULL;on_job_exit valid pjob: 0x30fe8d0 (substate=51)
10/24/2016 10:31:24;0008;PBS_Server;Job;NULL;on_job_exit valid pjob: 0x30fe8d0 (substate=52)
10/24/2016 10:31:24;0008;PBS_Server;Job;NULL;on_job_exit valid pjob: 0x30fe8d0 (substate=53)
10/24/2016 10:31:24;0040;PBS_Server;Svr;aegean;Scheduler was sent the command term
10/24/2016 10:35:14;0002;PBS_Server;Svr;PBS_Server;Torque Server Version = 3.0.3, loglevel = 0
10/24/2016 10:36:12;0008;PBS_Server;Job;NULL;on_job_exit valid pjob: 0x32438d0 (substate=59)
10/24/2016 10:36:12;0100;PBS_Server;Job;91651.aegean;dequeuing from long, state COMPLETE
10/24/2016 10:36:12;0040;PBS_Server;Svr;aegean;Scheduler was sent the command term
10/24/2016 10:36:24;0008;PBS_Server;Job;NULL;on_job_exit valid pjob: 0x30fe8d0 (substate=59)
10/24/2016 10:36:24;0100;PBS_Server;Job;91696.aegean;dequeuing from batch, state COMPLETE
10/24/2016 10:36:24;0040;PBS_Server;Svr;aegean;Scheduler was sent the command term
10/24/2016 10:38:26;0100;PBS_Server;Job;91717.aegean;enqueuing into batch, state 1 hop 1
10/24/2016 10:38:26;0008;PBS_Server;Job;91717.aegean;Job Queued at request of dangelid@aegean, owner = dangelid@aegean, job name = Wdg_1mm_0.4x0.3_dt_1ms_NOREINIT, queue = batch
10/24/2016 10:38:26;0040;PBS_Server;Svr;aegean;Scheduler was sent the command new
10/24/2016 10:38:27;0008;PBS_Server;Job;91717.aegean;Job Run at request of root@aegean
10/24/2016 10:38:27;000d;PBS_Server;Job;91717.aegean;Not sending email: User does not want mail of this type.
10/24/2016 10:40:14;0002;PBS_Server;Svr;PBS_Server;Torque Server Version = 3.0.3, loglevel = 0
10/24/2016 10:45:14;0002;PBS_Server;Svr;PBS_Server;Torque Server Version = 3.0.3, loglevel = 0
10/24/2016 10:48:26;0040;PBS_Server;Svr;aegean;Scheduler was sent the command time
10/24/2016 10:50:14;0002;PBS_Server;Svr;PBS_Server;Torque Server Version = 3.0.3, loglevel = 0
10/24/2016 10:55:14;0002;PBS_Server;Svr;PBS_Server;Torque Server Version = 3.0.3, loglevel = 0
10/24/2016 10:58:26;0040;PBS_Server;Svr;aegean;Scheduler was sent the command time
10/24/2016 11:00:14;0002;PBS_Server;Svr;PBS_Server;Torque Server Version = 3.0.3, loglevel = 0
10/24/2016 11:05:14;0002;PBS_Server;Svr;PBS_Server;Torque Server Version = 3.0.3, loglevel = 0
10/24/2016 11:08:26;0040;PBS_Server;Svr;aegean;Scheduler was sent the command time
10/24/2016 11:10:14;0002;PBS_Server;Svr;PBS_Server;Torque Server Version = 3.0.3, loglevel = 0
10/24/2016 11:15:14;0002;PBS_Server;Svr;PBS_Server;Torque Server Version = 3.0.3, loglevel = 0
10/24/2016 11:18:26;0040;PBS_Server;Svr;aegean;Scheduler was sent the command time
10/24/2016 11:20:14;0002;PBS_Server;Svr;PBS_Server;Torque Server Version = 3.0.3, loglevel = 0
10/24/2016 11:25:14;0002;PBS_Server;Svr;PBS_Server;Torque Server Version = 3.0.3, loglevel = 0
10/24/2016 11:28:26;0040;PBS_Server;Svr;aegean;Scheduler was sent the command time
10/24/2016 11:30:14;0002;PBS_Server;Svr;PBS_Server;Torque Server Version = 3.0.3, loglevel = 0
10/24/2016 11:35:14;0002;PBS_Server;Svr;PBS_Server;Torque Server Version = 3.0.3, loglevel = 0
10/24/2016 11:38:26;0040;PBS_Server;Svr;aegean;Scheduler was sent the command time
10/24/2016 11:40:14;0002;PBS_Server;Svr;PBS_Server;Torque Server Version = 3.0.3, loglevel = 0
10/24/2016 11:45:14;0002;PBS_Server;Svr;PBS_Server;Torque Server Version = 3.0.3, loglevel = 0
10/24/2016 11:48:26;0040;PBS_Server;Svr;aegean;Scheduler was sent the command time
10/24/2016 11:50:14;0002;PBS_Server;Svr;PBS_Server;Torque Server Version = 3.0.3, loglevel = 0
10/24/2016 11:54:10;0100;PBS_Server;Job;91718.aegean;enqueuing into batch, state 1 hop 1
10/24/2016 11:54:10;0008;PBS_Server;Job;91718.aegean;Job Queued at request of lixx5444@aegean, owner = lixx5444@aegean, job name = aegean_stream.sh, queue = batch
10/24/2016 11:54:10;0040;PBS_Server;Svr;aegean;Scheduler was sent the command new
10/24/2016 11:55:14;0002;PBS_Server;Svr;PBS_Server;Torque Server Version = 3.0.3, loglevel = 0
10/24/2016 12:00:14;0002;PBS_Server;Svr;PBS_Server;Torque Server Version = 3.0.3, loglevel = 0
10/24/2016 12:04:10;0040;PBS_Server;Svr;aegean;Scheduler was sent the command time
10/24/2016 12:05:14;0002;PBS_Server;Svr;PBS_Server;Torque Server Version = 3.0.3, loglevel = 0
10/24/2016 12:10:14;0002;PBS_Server;Svr;PBS_Server;Torque Server Version = 3.0.3, loglevel = 0
10/24/2016 12:14:10;0040;PBS_Server;Svr;aegean;Scheduler was sent the command time
10/24/2016 12:15:14;0002;PBS_Server;Svr;PBS_Server;Torque Server Version = 3.0.3, loglevel = 0
10/24/2016 12:20:14;0002;PBS_Server;Svr;PBS_Server;Torque Server Version = 3.0.3, loglevel = 0
10/24/2016 12:24:10;0040;PBS_Server;Svr;aegean;Scheduler was sent the command time
10/24/2016 12:25:14;0002;PBS_Server;Svr;PBS_Server;Torque Server Version = 3.0.3, loglevel = 0
10/24/2016 12:30:14;0002;PBS_Server;Svr;PBS_Server;Torque Server Version = 3.0.3, loglevel = 0
10/24/2016 12:34:10;0040;PBS_Server;Svr;aegean;Scheduler was sent the command time
10/24/2016 12:35:14;0002;PBS_Server;Svr;PBS_Server;Torque Server Version = 3.0.3, loglevel = 0
10/24/2016 12:40:14;0002;PBS_Server;Svr;PBS_Server;Torque Server Version = 3.0.3, loglevel = 0
10/24/2016 12:44:10;0040;PBS_Server;Svr;aegean;Scheduler was sent the command time
10/24/2016 12:45:14;0002;PBS_Server;Svr;PBS_Server;Torque Server Version = 3.0.3, loglevel = 0
10/24/2016 12:50:14;0002;PBS_Server;Svr;PBS_Server;Torque Server Version = 3.0.3, loglevel = 0
10/24/2016 12:54:10;0040;PBS_Server;Svr;aegean;Scheduler was sent the command time
10/24/2016 12:55:14;0002;PBS_Server;Svr;PBS_Server;Torque Server Version = 3.0.3, loglevel = 0
10/24/2016 13:00:14;0002;PBS_Server;Svr;PBS_Server;Torque Server Version = 3.0.3, loglevel = 0
10/24/2016 13:04:10;0040;PBS_Server;Svr;aegean;Scheduler was sent the command time
10/24/2016 13:05:14;0002;PBS_Server;Svr;PBS_Server;Torque Server Version = 3.0.3, loglevel = 0
10/24/2016 13:10:14;0002;PBS_Server;Svr;PBS_Server;Torque Server Version = 3.0.3, loglevel = 0
10/24/2016 13:14:10;0040;PBS_Server;Svr;aegean;Scheduler was sent the command time
10/24/2016 13:15:14;0002;PBS_Server;Svr;PBS_Server;Torque Server Version = 3.0.3, loglevel = 0
10/24/2016 13:20:14;0002;PBS_Server;Svr;PBS_Server;Torque Server Version = 3.0.3, loglevel = 0
10/24/2016 13:24:10;0040;PBS_Server;Svr;aegean;Scheduler was sent the command time
10/24/2016 13:25:14;0002;PBS_Server;Svr;PBS_Server;Torque Server Version = 3.0.3, loglevel = 0
10/24/2016 13:30:14;0002;PBS_Server;Svr;PBS_Server;Torque Server Version = 3.0.3, loglevel = 0
10/24/2016 13:34:10;0040;PBS_Server;Svr;aegean;Scheduler was sent the command time
10/24/2016 13:35:14;0002;PBS_Server;Svr;PBS_Server;Torque Server Version = 3.0.3, loglevel = 0
10/24/2016 13:40:14;0002;PBS_Server;Svr;PBS_Server;Torque Server Version = 3.0.3, loglevel = 0
10/24/2016 13:44:10;0040;PBS_Server;Svr;aegean;Scheduler was sent the command time
10/24/2016 13:45:14;0002;PBS_Server;Svr;PBS_Server;Torque Server Version = 3.0.3, loglevel = 0
10/24/2016 13:50:14;0002;PBS_Server;Svr;PBS_Server;Torque Server Version = 3.0.3, loglevel = 0
10/24/2016 13:54:10;0040;PBS_Server;Svr;aegean;Scheduler was sent the command time
10/24/2016 13:55:14;0002;PBS_Server;Svr;PBS_Server;Torque Server Version = 3.0.3, loglevel = 0
10/24/2016 14:00:14;0002;PBS_Server;Svr;PBS_Server;Torque Server Version = 3.0.3, loglevel = 0
10/24/2016 14:04:10;0040;PBS_Server;Svr;aegean;Scheduler was sent the command time
10/24/2016 14:05:14;0002;PBS_Server;Svr;PBS_Server;Torque Server Version = 3.0.3, loglevel = 0
10/24/2016 14:10:14;0002;PBS_Server;Svr;PBS_Server;Torque Server Version = 3.0.3, loglevel = 0
10/24/2016 14:14:10;0040;PBS_Server;Svr;aegean;Scheduler was sent the command time
10/24/2016 14:15:14;0002;PBS_Server;Svr;PBS_Server;Torque Server Version = 3.0.3, loglevel = 0
10/24/2016 14:20:14;0002;PBS_Server;Svr;PBS_Server;Torque Server Version = 3.0.3, loglevel = 0
10/24/2016 14:24:10;0040;PBS_Server;Svr;aegean;Scheduler was sent the command time
10/24/2016 14:25:14;0002;PBS_Server;Svr;PBS_Server;Torque Server Version = 3.0.3, loglevel = 0
10/24/2016 14:30:14;0002;PBS_Server;Svr;PBS_Server;Torque Server Version = 3.0.3, loglevel = 0
10/24/2016 14:34:10;0040;PBS_Server;Svr;aegean;Scheduler was sent the command time
10/24/2016 14:35:14;0002;PBS_Server;Svr;PBS_Server;Torque Server Version = 3.0.3, loglevel = 0
10/24/2016 14:40:14;0002;PBS_Server;Svr;PBS_Server;Torque Server Version = 3.0.3, loglevel = 0
10/24/2016 14:44:10;0040;PBS_Server;Svr;aegean;Scheduler was sent the command time
10/24/2016 14:45:14;0002;PBS_Server;Svr;PBS_Server;Torque Server Version = 3.0.3, loglevel = 0
10/24/2016 14:50:14;0002;PBS_Server;Svr;PBS_Server;Torque Server Version = 3.0.3, loglevel = 0
10/24/2016 14:54:10;0040;PBS_Server;Svr;aegean;Scheduler was sent the command time
10/24/2016 14:55:14;0002;PBS_Server;Svr;PBS_Server;Torque Server Version = 3.0.3, loglevel = 0
